The `try`, `catch`, and `finally` blocks in JavaScript are powerful constructs used to handle errors gracefully, allowing developers to prevent their applications from crashing due to unexpected conditions. Here's a detailed breakdown of these constructs with various examples, use cases, and nuances.

### **Basic Syntax**

```javascript
try {
  // Code that may throw an error
} catch (error) {
  // Code to handle the error
} finally {
  // Code that always executes regardless of whether an error occurred
}
```

### **1. The `try` Block**

The `try` block contains the code that you suspect may throw an error. If an error occurs in the `try` block, control is passed to the `catch` block. If no error occurs, the `catch` block is skipped.

### **2. The `catch` Block**

The `catch` block handles errors thrown from the `try` block. You can optionally capture the error object (commonly called `error` or `err`) to get details about the error.

### **3. The `finally` Block**

The `finally` block is optional but very useful. It always executes, regardless of whether an error occurred or not. This is often used for cleanup operations, such as closing database connections or releasing resources.

### **Example 1: Basic Try-Catch**

```javascript
try {
  if ((3 + 2) !== 4) {
    throw 'Not equal to 4';
  } else {
    console.log('2 + 2 is 4');
  }
} catch (err) {
  console.log('There is an error: ' + err);
}
// Output: "There is an error: Not equal to 4"
```

In this example:
- The code inside the `try` block checks if `3 + 2` is equal to `4`. Since it’s not, it throws an error with the message `'Not equal to 4'`.
- The `catch` block catches the error and prints the message.

### **Example 2: Using `finally` Block**

```javascript
try {
  if ((2 + 2) !== 4) {
    throw 'Not equal to 4';
  } else {
    console.log('2 + 2 is 4');
  }
} catch (err) {
  console.log('There is an error: ' + err);
} finally {
  console.log('This will execute regardless of the result.');
}
// Output:
// "2 + 2 is 4"
// "This will execute regardless of the result."
```

In this example:
- The `finally` block executes after the `try` (and `catch`, if present) blocks. It will always run, even if no error occurs.
  
### **Example 3: Using `catch` with Conditional Logic**

You can check the type of error by using conditional statements like `if`, `instanceof`, or `switch`.

```javascript
try {
  if ((2 + 2) !== 4) {
    throw new Error('It is not equal to 4');
  } else {
    return true;
  }
} catch (err) {
  if (err instanceof TypeError) {
    console.log(`There is a TypeError: ${err}`);
  } else if (err instanceof RangeError) {
    console.log(`There is a RangeError: ${err}`);
  } else {
    console.log(`There is a general error: ${err}`);
  }
}
// Output: "There is a general error: Error: It is not equal to 4"
```

In this example:
- The error type is checked using `instanceof` to determine whether it's a `TypeError`, `RangeError`, or any other error.

### **Example 4: Nested Try-Catch**

You can nest `try-catch` blocks to handle errors at different levels:

```javascript
try {
  try {
    throw 'I was inside the nested try at level 2';
  } finally {
    console.log('I will execute no matter what');
  }
} catch (err) {
  console.log(`There is an error caught at level 1: ${err}`);
}
// Output:
// "I will execute no matter what"
// "There is an error caught at level 1: I was inside the nested try at level 2"
```

In this example:
- The inner `try` throws an error, which is then handled by the `catch` block in the outer scope.
- The `finally` block always executes, regardless of whether an error is thrown or caught.

### **Example 5: Catching Errors and Re-Throwing Them**

You can catch an error, handle it, and then re-throw it to be handled at a higher level.

```javascript
try {
  try {
    throw 'I was inside the nested try at level 2';
  } catch (err) {
    console.log(`There is an error caught at level 2: ${err}`);
    throw 'I was inside the nested catch at level 2';  // Re-throwing error
  } finally {
    console.log('I will execute no matter what');
  }
} catch (err) {
  console.log(`There is an error caught at level 1: ${err}`);
}
// Output:
// "There is an error caught at level 2: I was inside the nested try at level 2"
// "I will execute no matter what"
// "There is an error caught at level 1: I was inside the nested catch at level 2"
```

In this example:
- After the error is caught in the inner `catch`, it is re-thrown, and the outer `catch` block catches and logs it.

### **Multiple Catch Blocks and Error Types**

JavaScript doesn't support multiple `catch` blocks as some other languages do, but you can differentiate error types inside a single `catch` block using conditionals.

```javascript
try {
  throw new RangeError('Out of range!');
} catch (err) {
  if (err instanceof RangeError) {
    console.log('RangeError caught: ' + err);
  } else if (err instanceof TypeError) {
    console.log('TypeError caught: ' + err);
  } else {
    console.log('Some other error caught: ' + err);
  }
}
// Output: "RangeError caught: Out of range!"
```

### **Example 6: Try without `catch` (Only `finally`)**

You can use `try` with only a `finally` block. This is useful when you need to ensure certain code is always executed, regardless of whether an error occurs.

```javascript
try {
  console.log('Trying something...');
} finally {
  console.log('I am finally free!');
}
// Output:
// "Trying something..."
// "I am finally free!"
```

### **Best Practices:**
1. **Always handle errors**: It's important to handle errors in a meaningful way to prevent your application from failing unexpectedly.
2. **Avoid empty `catch` blocks**: Empty `catch` blocks can silently ignore errors, making it difficult to debug.
3. **Use `finally` for cleanup**: Use `finally` for tasks that must be executed whether an error occurs or not, such as closing database connections, logging out users, or clearing resources.
4. **Error logging**: It’s good practice to log errors (using `console.error` or other logging mechanisms) for debugging and monitoring purposes.
5. **Don't swallow errors**: Avoid using `try-catch` in a way that swallows errors without logging or notifying the user.

### Conclusion:

JavaScript's `try`, `catch`, and `finally` provide a robust mechanism for error handling. By using these constructs effectively, you can prevent application crashes and provide more graceful error recovery and debugging capabilities.